# 用try，catch进行异常处理
```c++
#include<iostream>
using namespace std;
int main()
{
    double m,n;
    cin>>m>>n;
    try
    {
        cout<<"before dividing."<<endl;
        if(n==0)
            throw -1;    //抛出int类型异常
        else if(m==0)
            throw -1.0;    //抛出double类型异常
        else
            cout<<m/n<<endl;
        cout<<"after dividing."<<endl;
    }
    catch(double d)
    {
        cout<<"catch(double)"<<d<<endl;
    }
    catch(int e)
    {
        cout<<"catch(int)"<<e<<endl;
    }
    cout<<"finished"<<endl;
    return 0;
}
/*
输入“9 6”
输出：
before dividing.
1.5
after dividing.
finished 
*/
```    
* try块中定义的局部对象，发生异常时会析构
# 异常的再抛出
* 如果一个函数在执行的过程中，抛出异常在本函数内就被catch块捕获并处理了，那么该异常就不会抛给这个函数的调用者（也称“上一层的函数”）；如果异常在本函数中没有处理，就会被抛给上一层的函数
# c++标准异常类
* c++标准库中有一些类代表异常，这些类都是从exception类派生出来的
![Alt text](image-69.png)     
